Workbook

Sheet DETAILPER TARIF
A1: DATA PENJUALAN TAHUN 2024-2025
A2: PLN UP3 MALANG
A3: NO | B3: TAHUN | C3: BULAN | D3: JUMLAH PELANGGAN PER TARIF (PLG) | J3: JUMLAH KWH PENJUALAN PER TARIF ( KWH )
D4: S | E4: R | F4: B | G4: I | H4: P | I4: TOTAL | J4: S | K4: R | L4: B | M4: I | N4: P | O4: TOTAL
A5: 1 | B5: 2024 | C5: JANUARI | D5: 33286 | E5: 1233417 | F5: 58092 | G5: 1691 | H5: 7276 | I5: =SUM(D5:H5) -> 1333762 | J5: 14699314 | K5: 125266546 | L5: 44895606 | M5: 51646324 | N5: 7965188 | O5: =SUM(J5:N5) -> 244472978
A6: 2 | B6: 2024 | C6: FEBRUARI | D6: 33381 | E6: 1235927 | F6: 58326 | G6: 1690 | H6: 7296 | I6: =SUM(D6:H6) -> 1336620 | J6: 14186304 | K6: 118036012 | L6: 42425779 | M6: 46878400 | N6: 7610347 | O6: =SUM(J6:N6) -> 229136842
A7: 3 | B7: 2024 | C7: MARET | D7: 33486 | E7: 1238697 | F7: 58586 | G7: 1694 | H7: 7310 | I7: =SUM(D7:H7) -> 1339773 | J7: 15311093 | K7: 128398977 | L7: 44907342 | M7: 50409920 | N7: 7827632 | O7: =SUM(J7:N7) -> 246854964
A8: 4 | B8: 2024 | C8: APRIL | D8: 33540 | E8: 1240860 | F8: 58766 | G8: 1696 | H8: 7323 | I8: =SUM(D8:H8) -> 1342185 | J8: 13880130 | K8: 126636893 | L8: 43802890 | M8: 40691317 | N8: 7599479 | O8: =SUM(J8:N8) -> 232610709
A9: 5 | B9: 2024 | C9: MEI | D9: 33601 | E9: 1244248 | F9: 59081 | G9: 1704 | H9: 7343 | I9: =SUM(D9:H9) -> 1345977 | J9: 15647165 | K9: 129496742 | L9: 47184020 | M9: 54084649 | N9: 7963068 | O9: =SUM(J9:N9) -> 254375644
A10: 6 | B10: 2024 | C10: JUNI | D10: 33671 | E10: 1247598 | F10: 59388 | G10: 1708 | H10: 7377 | I10: =SUM(D10:H10) -> 1349742 | J10: 14305051 | K10: 125288112 | L10: 45188153 | M10: 52775360 | N10: 7751756 | O10: =SUM(J10:N10) -> 245308432
A11: 7 | B11: 2024 | C11: JULI | D11: 33778 | E11: 1251365 | F11: 59682 | G11: 1712 | H11: 7407 | I11: =SUM(D11:H11) -> 1353944 | J11: 13971808 | K11: 125127669 | L11: 45664915 | M11: 57038836 | N11: 7846503 | O11: =SUM(J11:N11) -> 249649731
A12: 8 | B12: 2024 | C12: AGUSTUS | D12: 33887 | E12: 1256008 | F12: 59963 | G12: 1724 | H12: 7461 | I12: =SUM(D12:H12) -> 1359043 | J12: 14739192 | K12: 125557506 | L12: 45250460 | M12: 56293665 | N12: 7903727 | O12: =SUM(J12:N12) -> 249744550
A13: 9 | B13: 2024 | C13: SEPTEMBER | D13: 33961 | E13: 1261220 | F13: 60244 | G13: 1743 | H13: 7505 | I13: =SUM(D13:H13) -> 1364673 | J13: 15758181 | K13: 125341455 | L13: 45659563 | M13: 55758981 | N13: 7896790 | O13: =SUM(J13:N13) -> 250414970
A14: 10 | B14: 2024 | C14: OKTOBER | D14: 34035 | E14: 1265315 | F14: 60596 | G14: 1761 | H14: 7537 | I14: =SUM(D14:H14) -> 1369244 | J14: 17474972 | K14: 133219484 | L14: 49139167 | M14: 59986311 | N14: 8322192 | O14: =SUM(J14:N14) -> 268142126
A15: 11 | B15: 2024 | C15: NOPEMBER | D15: 34111 | E15: 1269002 | F15: 60933 | G15: 1775 | H15: 7583 | I15: =SUM(D15:H15) -> 1373404 | J15: 16871210 | K15: 129978043 | L15: 47970935 | M15: 55681807 | N15: 8152362 | O15: =SUM(J15:N15) -> 258654357
A16: 12 | B16: 2024 | C16: DESEMBER | D16: 34184 | E16: 1272307 | F16: 61281 | G16: 1795 | H16: 7649 | I16: =SUM(D16:H16) -> 1377216 | J16: 15674361 | K16: 131971537 | L16: 49215805 | M16: 53032570 | N16: 8170841 | O16: =SUM(J16:N16) -> 258065114
... A28: 24 | B28: 2025 | C28: DESEMBER | D28: 35045 | E28: 1313684 | F28: 65173 | G28: 2088 | H28: 8069 | I28: =SUM(D28:H28) -> 1424059 | J28: 16967888 | K28: 135161463 | L28: 52285235 | M28: 60501434 | N28: 7930409 | O28: =SUM(J28:N28) -> 272846429

Sheet Lembar1
C5: DATA PENJUALAN PLN UP3 MALANG
C6: No | D6: Tahun | E6: Bulan | F6: Jumlah Pelanggan | G6: DELTA PELANGGAN | H6: kwh jual ( kwh ) | I6: DELTA KWH JUAL | J6: HARI JUAL PER BULAN | K6: KWH JUAL PER HARI | L6: DELTA JUAL KWH HARIAN | M6: THN 2024 VS 2025
C7: 1 | D7: 2024 | E7: Januari | F7: ='DETAILPER TARIF'!I5 -> 1333762 | H7: ='DETAILPER TARIF'!O5 -> 244472978 | J7: 31 | K7: =H7/J7 -> 7886225.1
C8: 2 | D8: 2024 | E8: Februari | F8: ='DETAILPER TARIF'!I6 -> 1336620 | G8: =F8-F7 -> 2858 | H8: ='DETAILPER TARIF'!O6 -> 229136842 | I8: =H8-H7 -> -15336136 | J8: 28 | K8: =H8/J8 -> 8183458.6 | L8: =K8-K7 -> 297233.55
C9: 3 | D9: 2024 | E9: Maret | F9: ='DETAILPER TARIF'!I7 -> 1339773 | G9: =F9-F8 -> 3153 | H9: ='DETAILPER TARIF'!O7 -> 246854964 | I9: =H9-H8 -> 17718122 | J9: 31 | K9: =H9/J9 -> 7963063.4 | L9: =K9-K8 -> -220395.29
C10: 4 | D10: 2024 | E10: April | F10: ='DETAILPER TARIF'!I8 -> 1342185 | G10: =F10-F9 -> 2412 | H10: ='DETAILPER TARIF'!O8 -> 232610709 | I10: =H10-H9 -> -14244255 | J10: 30 | K10: =H10/J10 -> 7753690.3 | L10: =K10-K9 -> -209373.05
C11: 5 | D11: 2024 | E11: Mei | F11: ='DETAILPER TARIF'!I9 -> 1345977 | G11: =F11-F10 -> 3792 | H11: ='DETAILPER TARIF'!O9 -> 254375644 | I11: =H11-H10 -> 21764935 | J11: 31 | K11: =H11/J11 -> 8205665.9 | L11: =K11-K10 -> 451975.64
C12: 6 | D12: 2024 | E12: Juni | F12: ='DETAILPER TARIF'!I10 -> 1349742 | G12: =F12-F11 -> 3765 | H12: ='DETAILPER TARIF'!O10 -> 245308432 | I12: =H12-H11 -> -9067212 | J12: 30 | K12: =H12/J12 -> 8176947.7 | L12: =K12-K11 -> -28718.202
C13: 7 | D13: 2024 | E13: Juli | F13: ='DETAILPER TARIF'!I11 -> 1353944 | G13: =F13-F12 -> 4202 | H13: ='DETAILPER TARIF'!O11 -> 249649731 | I13: =H13-H12 -> 4341299 | J13: 31 | K13: =H13/J13 -> 8053217.1 | L13: =K13-K12 -> -123730.6
C14: 8 | D14: 2024 | E14: Agustus | F14: ='DETAILPER TARIF'!I12 -> 1359043 | G14: =F14-F13 -> 5099 | H14: ='DETAILPER TARIF'!O12 -> 249744550 | I14: =H14-H13 -> 94819 | J14: 31 | K14: =H14/J14 -> 8056275.8 | L14: =K14-K13 -> 3058.6774
C15: 9 | D15: 2024 | E15: September | F15: ='DETAILPER TARIF'!I13 -> 1364673 | G15: =F15-F14 -> 5630 | H15: ='DETAILPER TARIF'!O13 -> 250414970 | I15: =H15-H14 -> 670420 | J15: 30 | K15: =H15/J15 -> 8347165.7 | L15: =K15-K14 -> 290889.86
C16: 10 | D16: 2024 | E16: Oktober | F16: ='DETAILPER TARIF'!I14 -> 1369244 | G16: =F16-F15 -> 4571 | H16: ='DETAILPER TARIF'!O14 -> 268142126 | I16: =H16-H15 -> 17727156 | J16: 31 | K16: =H16/J16 -> 8649746 | L16: =K16-K15 -> 302580.33
C17: 11 | D17: 2024 | E17: November | F17: ='DETAILPER TARIF'!I15 -> 1373404 | G17: =F17-F16 -> 4160 | H17: ='DETAILPER TARIF'!O15 -> 258654357 | I17: =H17-H16 -> -9487769 | J17: 30 | K17: =H17/J17 -> 8621811.9 | L17: =K17-K16 -> -27934.1
C18: 12 | D18: 2024 | E18: Desember | F18: ='DETAILPER TARIF'!I16 -> 1377216 | G18: =F18-F17 -> 3812 | H18: ='DETAILPER TARIF'!O16 -> 258065114 | I18: =H18-H17 -> -589243 | J18: 31 | K18: =H18/J18 -> 8324681.1 | L18: =K18-K17 -> -297130.8
C19: 13 | D19: 2025 | E19: Januari | F19: ='DETAILPER TARIF'!I17 -> 1380672 | G19: =F19-F18 -> 3456 | H19: ='DETAILPER TARIF'!O17 -> 302304163 | I19: =H19-H18 -> 44239049 | J19: 31 | K19: =H19/J19 -> 9751747.2 | L19: =K19-K18 -> 1427066.1
C20: 14 | D20: 2025 | E20: Februari | F20: ='DETAILPER TARIF'!I18 -> 1384049 | G20: =F20-F19 -> 3377 | H20: ='DETAILPER TARIF'!O18 -> 277964332 | I20: =H20-H19 -> -24339831 | J20: 28 | K20: =H20/J20 -> 9927297.6 | L20: =K20-K19 -> 175550.38 | M20: =L20-L8 -> -121683.17
C21: 15 | D21: 2025 | E21: Maret | F21: ='DETAILPER TARIF'!I19 -> 1387620 | G21: =F21-F20 -> 3571 | H21: ='DETAILPER TARIF'!O19 -> 266409634 | I21: =H21-H20 -> -11554698 | J21: 31 | K21: =H21/J21 -> 8593859.2 | L21: =K21-K20 -> -1333438.4 | M21: =L21-L9 -> -1113043.1
C22: 16 | D22: 2025 | E22: April | F22: ='DETAILPER TARIF'!I20 -> 1390355 | G22: =F22-F21 -> 2735 | H22: ='DETAILPER TARIF'!O20 -> 227082949 | I22: =H22-H21 -> -39326685 | J22: 30 | K22: =H22/J22 -> 7569431.6 | L22: =K22-K21 -> -1024427.5 | M22: =L22-L10 -> -815054.47
C23: 17 | D23: 2025 | E23: Mei | F23: ='DETAILPER TARIF'!I21 -> 1394247 | G23: =F23-F22 -> 3892 | H23: ='DETAILPER TARIF'!O21 -> 249837247 | I23: =H23-H22 -> 22754298 | J23: 31 | K23: =H23/J23 -> 8059266 | L23: =K23-K22 -> 489834.4 | M23: =L23-L11 -> 37858.763
C24: 18 | D24: 2025 | E24: Juni | F24: ='DETAILPER TARIF'!I22 -> 1398106 | G24: =F24-F23 -> 3859 | H24: ='DETAILPER TARIF'!O22 -> 247421397 | I24: =H24-H23 -> -2415850 | J24: 30 | K24: =H24/J24 -> 8247379.9 | L24: =K24-K23 -> 188113.87 | M24: =L24-L12 -> 216832.07
C25: 19 | D25: 2025 | E25: Juli | F25: ='DETAILPER TARIF'!I23 -> 1402306 | G25: =F25-F24 -> 4200 | H25: ='DETAILPER TARIF'!O23 -> 254014189 | I25: =H25-H24 -> 6592792 | J25: 31 | K25: =H25/J25 -> 8194006.1 | L25: =K25-K24 -> -53373.803 | M25: =L25-L13 -> 70356.801
C26: 20 | D26: 2025 | E26: Agustus | F26: ='DETAILPER TARIF'!I24 -> 1406475 | G26: =F26-F25 -> 4169 | H26: ='DETAILPER TARIF'!O24 -> 257714807 | I26: =H26-H25 -> 3700618 | J26: 31 | K26: =H26/J26 -> 8313380.9 | L26: =K26-K25 -> 119374.77 | M26: =L26-L14 -> 116316.1
C27: 21 | D27: 2025 | E27: September | F27: ='DETAILPER TARIF'!I25 -> 1410489 | G27: =F27-F26 -> 4014 | H27: ='DETAILPER TARIF'!O25 -> 260260599 | I27: =H27-H26 -> 2545792 | J27: 30 | K27: =H27/J27 -> 8675353.3 | L27: =K27-K26 -> 361972.43 | M27: =L27-L15 -> 71082.569
C28: 22 | D28: 2025 | E28: Oktober | F28: ='DETAILPER TARIF'!I26 -> 1414438 | G28: =F28-F27 -> 3949 | H28: ='DETAILPER TARIF'!O26 -> 276221227 | I28: =H28-H27 -> 15960628 | J28: 31 | K28: =H28/J28 -> 8910362.2 | L28: =K28-K27 -> 235008.86 | M28: =L28-L16 -> -67571.472
C29: 23 | D29: 2025 | E29: November | F29: ='DETAILPER TARIF'!I27 -> 1418796 | G29: =F29-F28 -> 4358 | H29: ='DETAILPER TARIF'!O27 -> 264749129 | I29: =H29-H28 -> -11472098 | J29: 30 | K29: =H29/J29 -> 8824971 | L29: =K29-K28 -> -85391.195 | M29: =L29-L17 -> -57457.095
C30: 24 | D30: 2025 | E30: Desember | F30: ='DETAILPER TARIF'!I28 -> 1424059 | G30: =F30-F29 -> 5263 | H30: ='DETAILPER TARIF'!O28 -> 272846429 | I30: =H30-H29 -> 8097300 | J30: 31 | K30: =H30/J30 -> 8801497.7 | L30: =K30-K29 -> -23473.257 | M30: =L30-L18 -> 273657.55
G31: =SUM(G8:G30) -> 90297
B38: Y | C38: X | D38: X^2 | E38: X^4 | F38: XY | G38: X^2Y
B39: =SUM(F7:F30) -> 33057195 | C39: -12 | D39: =C39^2 -> 144 | E39: =C39^4 -> 20736 | F39: =C39*F7 -> -16005144 | G39: =D39*F7 -> 192061728
C40: -11 | D40: =C40^2 -> 121 | E40: =C40^4 -> 14641 | F40: =C40*F8 -> -14702820 | G40: =D40*F8 -> 161731020 | J40: b | K40: =F63/D63 -> 3711.0862
C41: -10 | D41: =C41^2 -> 100 | E41: =C41^4 -> 10000 | F41: =C41*F9 -> -13397730 | G41: =D41*F9 -> 133977300 | J41: a | K41: =((B39*E63)-(G63*D63))/(24*E63-D63^2) -> 1377474
C42: -9 | D42: =C42^2 -> 81 | E42: =C42^4 -> 6561 | F42: =C42*F10 -> -12079665 | G42: =D42*F10 -> 108716985 | J42: c | K42: =((24*G63)-(D63*B39))/(24*E63-D63^2) -> -1.6774296
C43: -8 | D43: =C43^2 -> 64 | E43: =C43^4 -> 4096 | F43: =C43*F11 -> -10767816 | G43: =D43*F11 -> 86142528 | J43: persamaan tren parabola
C44: -7 | D44: =C44^2 -> 49 | E44: =C44^4 -> 2401 | F44: =C44*F12 -> -9448194 | G44: =D44*F12 -> 66137358 | J44: Y = 1,377,473.99 + 3,711.09 (X) - 1.68 (X^2) | M44: jumlah pelanggan cenderung naik, tapi pola kenaikan sedikit melambat
C45: -6 | D45: =C45^2 -> 36 | E45: =C45^4 -> 1296 | F45: =C45*F13 -> -8123664 | G45: =D45*F13 -> 48741984
C46: -5 | D46: =C46^2 -> 25 | E46: =C46^4 -> 625 | F46: =C46*F14 -> -6795215 | G46: =D46*F14 -> 33976075 | J46: rata-rata pertumbuhan pelanggan | L46: =G31/24 -> 3762.375
C47: -4 | D47: =C47^2 -> 16 | E47: =C47^4 -> 256 | F47: =C47*F15 -> -5458692 | G47: =D47*F15 -> 21834768
C48: -3 | D48: =C48^2 -> 9 | E48: =C48^4 -> 81 | F48: =C48*F16 -> -4107732 | G48: =D48*F16 -> 12323196
C49: -2 | D49: =C49^2 -> 4 | E49: =C49^4 -> 16 | F49: =C49*F17 -> -2746808 | G49: =D49*F17 -> 5493616
C50: -1 | D50: =C50^2 -> 1 | E50: =C50^4 -> 1 | F50: =C50*F18 -> -1377216 | G50: =D50*F18 -> 1377216
...

Sheet Sheet1
A1: Tabel Distribusi Frekuensi
A2: Kelas | D2: Frekuensi | E2: fk* | F2: mi | G2: mi.fi
A3: 1333762 | B3: - | C3: 1348811 | D3: 5 | E3: =D3 -> 5 | F3: =1/2*(A3+C3) -> 1341286.5 | G3: =F3*D3 -> 6706432.5
A4: 1348812 | B4: - | C4: 1363861 | D4: 3 | E4: =E3+D4 -> 8 | F4: =1/2*(A4+C4) -> 1356336.5 | G4: =F4*D4 -> 4069009.5
A5: 1363862 | B5: - | C5: 1378911 | D5: 4 | E5: =E4+D5 -> 12 | F5: =1/2*(A5+C5) -> 1371386.5 | G5: =F5*D5 -> 5485546
A6: 1378912 | B6: - | C6: 1393961 | D6: 4 | E6: =E5+D6 -> 16 | F6: =1/2*(A6+C6) -> 1386436.5 | G6: =F6*D6 -> 5545746
A7: 1393962 | B7: - | C7: 1409011 | D7: 4 | E7: =E6+D7 -> 20 | F7: =1/2*(A7+C7) -> 1401486.5 | G7: =F7*D7 -> 5605946
A8: 1409012 | B8: - | C8: 1424061 | D8: 4 | E8: =E7+D8 -> 24 | F8: =1/2*(A8+C8) -> 1416536.5 | G8: =F8*D8 -> 5666146
D9: =SUM(D3:D8) -> 24 | G9: =SUM(G3:G8) -> 33078826
B12: Mean | C12: =G9/D9 -> 1378284.4
B13: Median | C13: =(A5-0.5)+15049.5*(((D9/2)-E4)/D5) -> 1378911
B14: Modus | C14: =(A3-0.5)+15049.5*(5/(5+8)) -> 1339549.8
B15: Nilai Maksimal | C15: =MAX(Lembar1!F7:F30) -> 1424059
B16: Nilai Minimal | C16: =MIN(Lembar1!F7:F30) -> 1333762
B17: Range | C17: =C15-C16 -> 90297
